<mujoco>
  <visual>
    <headlight diffuse="0.6 0.6 0.6" ambient="0.3 0.3 0.3" specular="0 0 0"/>
    <rgba haze="0.15 0.25 0.35 1"/>
    <global azimuth="-120" elevation="-20"/>
  </visual>

  <asset>
    <texture type="skybox" builtin="gradient" rgb1="0.3 0.5 0.7" rgb2="0 0 0" width="512" height="3072"/>
    <texture type="2d" name="groundplane" builtin="checker" mark="edge" rgb1="0.2 0.3 0.4" rgb2="0.1 0.2 0.3"
      markrgb="0.8 0.8 0.8" width="300" height="300"/>
    <material name="groundplane" texture="groundplane" texuniform="true" texrepeat="5 5" reflectance="0.2"/>
  </asset>

  <option gravity="0 0 -9.81" />

  <worldbody>
    <light pos="0 0 1.5" dir="0 0 -1" directional="true"/>
    <geom name="floor" size="0 0 0.05" type="plane" material="groundplane"/>

    <!-- Add a stand for the first link -->
    <body name="stand" pos="0 0 0.5">
      <geom type="cylinder" size="0.3 0.5 0" rgba="0.8 0.8 0.8 1" mass="1"/>
    

      <body pos="-0.5 0 0.55" euler="0 90 0">
        <joint name="joint0" type="hinge" axis="-1 0 0" pos="0 0 0.5"/>
        <geom type="cylinder" size="0.05 0.5" rgba="0 1 0 1" mass="1"/>

        <body pos="-0.5 0 -0.5" euler="90 90 0">
          <joint name="joint1" type="hinge" axis="0 -1 0" pos="0 0 0.5"/>
          <geom type="cylinder" size="0.05 0.5" rgba="1 0 0 1" mass="1"/>
        </body>
      </body>
    </body>
  </worldbody>

  <actuator>
    <motor name="torque0" joint="joint0" gear="1"/>
    <motor name="torque1" joint="joint1" gear="1"/>
  </actuator>

  <sensor>
    <jointpos name="j1" joint="joint0"/>
    <jointpos name="j2" joint="joint1"/>
  </sensor>
</mujoco>